============================= test session starts =============================
platform win32 -- Python 3.9.0, pytest-6.2.4, py-1.11.0, pluggy-0.13.1 -- f:\Python\_Dev\api_yamdb\.venv\Scripts\python.exe
django: settings: api_yamdb.settings (from ini)
rootdir: F:\Python\_Dev\api_yamdb\api_yamdb, configfile: pytest.ini, testpaths: tests/
plugins: pythonpath-0.7.3, django-4.4.0
collecting ... collected 80 items

tests/test_00_user_registration.py::Test00UserRegistration::test_00_nodata_signup PASSED [  1%]
tests/test_00_user_registration.py::Test00UserRegistration::test_00_invalid_data_signup PASSED [  2%]
tests/test_00_user_registration.py::Test00UserRegistration::test_00_singup_length_and_simbols_validation[data0-messege0] PASSED [  3%]
tests/test_00_user_registration.py::Test00UserRegistration::test_00_singup_length_and_simbols_validation[data1-messege1] PASSED [  5%]
tests/test_00_user_registration.py::Test00UserRegistration::test_00_singup_length_and_simbols_validation[data2-messege2] PASSED [  6%]
tests/test_00_user_registration.py::Test00UserRegistration::test_00_valid_data_user_signup PASSED [  7%]
tests/test_00_user_registration.py::Test00UserRegistration::test_00_valid_data_admin_create_user PASSED [  8%]
tests/test_00_user_registration.py::Test00UserRegistration::test_00_admin_create_user_length_and_simbols_validation[data0-messege0] PASSED [ 10%]
tests/test_00_user_registration.py::Test00UserRegistration::test_00_admin_create_user_length_and_simbols_validation[data1-messege1] PASSED [ 11%]
tests/test_00_user_registration.py::Test00UserRegistration::test_00_admin_create_user_length_and_simbols_validation[data2-messege2] PASSED [ 12%]
tests/test_00_user_registration.py::Test00UserRegistration::test_00_admin_create_user_length_and_simbols_validation[data3-messege3] PASSED [ 13%]
tests/test_00_user_registration.py::Test00UserRegistration::test_00_admin_create_user_length_and_simbols_validation[data4-messege4] PASSED [ 15%]
tests/test_00_user_registration.py::Test00UserRegistration::test_00_obtain_jwt_token_invalid_data PASSED [ 16%]
tests/test_00_user_registration.py::Test00UserRegistration::test_00_registration_me_username_restricted PASSED [ 17%]
tests/test_00_user_registration.py::Test00UserRegistration::test_00_registration_same_email_restricted PASSED [ 18%]
tests/test_00_user_registration.py::Test00UserRegistration::test_get_new_confirmation_code_for_existing_user FAILED [ 20%]
tests/test_00_user_registration.py::Test00UserRegistration::test_get_confirmation_code_for_user_created_by_admin FAILED [ 21%]
tests/test_01_users.py::Test01UserAPI::test_01_users_not_authenticated PASSED [ 22%]
tests/test_01_users.py::Test01UserAPI::test_02_users_username_not_authenticated PASSED [ 23%]
tests/test_01_users.py::Test01UserAPI::test_03_users_me_not_authenticated PASSED [ 25%]
tests/test_01_users.py::Test01UserAPI::test_04_users_get_admin PASSED    [ 26%]
tests/test_01_users.py::Test01UserAPI::test_04_02_users_get_search FAILED [ 27%]
tests/test_01_users.py::Test01UserAPI::test_04_01_users_get_admin_only PASSED [ 28%]
tests/test_01_users.py::Test01UserAPI::test_05_01_users_post_admin_bad_requests PASSED [ 30%]
tests/test_01_users.py::Test01UserAPI::test_05_02_users_post_admin_user_creation[data0-] PASSED [ 31%]
tests/test_01_users.py::Test01UserAPI::test_05_02_users_post_admin_user_creation[data1-без указани€ роли нового пользовател€ ] PASSED [ 32%]
tests/test_01_users.py::Test01UserAPI::test_05_03_users_post_response_has_data PASSED [ 33%]
tests/test_01_users.py::Test01UserAPI::test_05_04_users_post_user_superuser PASSED [ 35%]
tests/test_01_users.py::Test01UserAPI::test_06_users_username_get_admin PASSED [ 36%]
tests/test_01_users.py::Test01UserAPI::test_06_users_username_get_not_admin PASSED [ 37%]
tests/test_01_users.py::Test01UserAPI::test_07_01_users_username_patch_admin PASSED [ 38%]
tests/test_01_users.py::Test01UserAPI::test_07_02_users_username_patch_moderator PASSED [ 40%]
tests/test_01_users.py::Test01UserAPI::test_07_03_users_username_patch_user PASSED [ 41%]
tests/test_01_users.py::Test01UserAPI::test_07_05_users_username_put_not_allowed FAILED [ 42%]
tests/test_01_users.py::Test01UserAPI::test_08_01_users_username_delete_admin PASSED [ 43%]
tests/test_01_users.py::Test01UserAPI::test_08_02_users_username_delete_moderator PASSED [ 45%]
tests/test_01_users.py::Test01UserAPI::test_08_03_users_username_delete_user PASSED [ 46%]
tests/test_01_users.py::Test01UserAPI::test_08_04_users_username_delete_superuser PASSED [ 47%]
tests/test_01_users.py::Test01UserAPI::test_09_users_me_get FAILED       [ 48%]
tests/test_01_users.py::Test01UserAPI::test_09_02_users_me_delete_not_allowed PASSED [ 50%]
tests/test_01_users.py::Test01UserAPI::test_10_01_users_me_patch FAILED  [ 51%]
tests/test_01_users.py::Test01UserAPI::test_10_02_users_me_has_field_validation[data0-messege0] FAILED [ 52%]
tests/test_01_users.py::Test01UserAPI::test_10_02_users_me_has_field_validation[data1-messege1] FAILED [ 53%]
tests/test_01_users.py::Test01UserAPI::test_10_02_users_me_has_field_validation[data2-messege2] FAILED [ 55%]
tests/test_01_users.py::Test01UserAPI::test_10_02_users_me_has_field_validation[data3-messege3] FAILED [ 56%]
tests/test_01_users.py::Test01UserAPI::test_10_02_users_me_has_field_validation[data4-messege4] FAILED [ 57%]
tests/test_01_users.py::Test01UserAPI::test_10_03_users_me_patch_change_role_not_allowed FAILED [ 58%]
tests/test_02_category.py::Test02CategoryAPI::test_01_category_not_auth PASSED [ 60%]
tests/test_02_category.py::Test02CategoryAPI::test_02_category_with_admin_user PASSED [ 61%]
tests/test_02_category.py::Test02CategoryAPI::test_03_category_fields_validation[data0-massage0] PASSED [ 62%]
tests/test_02_category.py::Test02CategoryAPI::test_03_category_fields_validation[data1-massage1] PASSED [ 63%]
tests/test_02_category.py::Test02CategoryAPI::test_03_category_fields_validation[data2-massage2] PASSED [ 65%]
tests/test_02_category.py::Test02CategoryAPI::test_04_category_delete_admin FAILED [ 66%]
tests/test_02_category.py::Test02CategoryAPI::test_05_category_check_permission_admin PASSED [ 67%]
tests/test_03_genre.py::Test03GenreAPI::test_01_genre_not_auth PASSED    [ 68%]
tests/test_03_genre.py::Test03GenreAPI::test_02_genre PASSED             [ 70%]
tests/test_03_genre.py::Test03GenreAPI::test_03_category_fields_validation[data0-massage0] PASSED [ 71%]
tests/test_03_genre.py::Test03GenreAPI::test_03_category_fields_validation[data1-massage1] PASSED [ 72%]
tests/test_03_genre.py::Test03GenreAPI::test_03_category_fields_validation[data2-massage2] PASSED [ 73%]
tests/test_03_genre.py::Test03GenreAPI::test_04_genres_delete FAILED     [ 75%]
tests/test_03_genre.py::Test03GenreAPI::test_05_genres_check_permission PASSED [ 76%]
tests/test_04_title.py::Test04TitleAPI::test_01_title_not_auth PASSED    [ 77%]
tests/test_04_title.py::Test04TitleAPI::test_02_title_admin FAILED       [ 78%]
tests/test_04_title.py::Test04TitleAPI::test_03_titles_detail PASSED     [ 80%]
tests/test_04_title.py::Test04TitleAPI::test_04_titles_name_length_validation PASSED [ 81%]
tests/test_04_title.py::Test04TitleAPI::test_05_titles_check_permission PASSED [ 82%]
tests/test_04_title.py::Test04TitleAPI::test_06_titles_detail_put_not_allowed PASSED [ 83%]
tests/test_05_review.py::Test05ReviewAPI::test_01_review_not_auth PASSED [ 85%]
tests/test_05_review.py::Test05ReviewAPI::test_02_review_post FAILED     [ 86%]
tests/test_05_review.py::Test05ReviewAPI::test_03_review_detail_get FAILED [ 87%]
tests/test_05_review.py::Test05ReviewAPI::test_04_review_detail_user PASSED [ 88%]
tests/test_05_review.py::Test05ReviewAPI::test_05_reviews_detail_moderator_and_admin PASSED [ 90%]
tests/test_05_review.py::Test05ReviewAPI::test_06_reviews_detail_put_not_allowed PASSED [ 91%]
tests/test_06_comment.py::Test06CommentAPI::test_01_comment_not_auth FAILED [ 92%]
tests/test_06_comment.py::Test06CommentAPI::test_02_comment FAILED       [ 93%]
tests/test_06_comment.py::Test06CommentAPI::test_03_comment_detail_get FAILED [ 95%]
tests/test_06_comment.py::Test06CommentAPI::test_04_comment_detail__user_patch_delete FAILED [ 96%]
tests/test_06_comment.py::Test06CommentAPI::test_05_comment_detail_admin_and_moderator FAILED [ 97%]
tests/test_06_comment.py::Test06CommentAPI::test_06_comment_detail_not_auth FAILED [ 98%]
tests/test_06_comment.py::Test06CommentAPI::test_07_comment_detail_put_not_allowed FAILED [100%]

================================== FAILURES ===================================
___ Test00UserRegistration.test_get_new_confirmation_code_for_existing_user ___

self = <tests.test_00_user_registration.Test00UserRegistration object at 0x0000010FFF8D2100>
client = <django.test.client.Client object at 0x0000010FFF8F57C0>

    def test_get_new_confirmation_code_for_existing_user(self, client):
        valid_data = {
            'email': 'test_email@yamdb.fake',
            'username': 'valid_username_1'
        }
        response = client.post(self.URL_SIGNUP, data=valid_data)
        assert response.status_code == HTTPStatus.OK, (
            'ѕроверьте, что POST-запрос с корректными данными, отправленный '
            f'на эндпоинт `{self.URL_SIGNUP}`, возвращает ответ со статусом '
            '200.'
        )
    
        response = client.post(self.URL_SIGNUP, data=valid_data)
>       assert response.status_code == HTTPStatus.OK, (
            f'ѕроверьте, что повторный POST-запрос к `{self.URL_SIGNUP}` с '
            'данными зарегистрированного пользовател€ возвращает ответ со '
            'статусом 200.'
        )
E       AssertionError: ѕроверьте, что повторный POST-запрос к `/api/v1/auth/signup/` с данными зарегистрированного пользовател€ возвращает ответ со статусом 200.
E       assert 400 == <HTTPStatus.OK: 200>
E         +400
E         -<HTTPStatus.OK: 200>

tests\test_00_user_registration.py:351: AssertionError
------------------------------ Captured log call ------------------------------
WARNING  django.request:log.py:224 Bad Request: /api/v1/auth/signup/
_ Test00UserRegistration.test_get_confirmation_code_for_user_created_by_admin _

self = <tests.test_00_user_registration.Test00UserRegistration object at 0x0000010FFF911670>
admin_client = <rest_framework.test.APIClient object at 0x0000010FFF8F5FD0>
client = <django.test.client.Client object at 0x0000010FFF900400>
django_user_model = <class 'users.models.YamdbUser'>

    def test_get_confirmation_code_for_user_created_by_admin(
            self, admin_client, client, django_user_model
    ):
        user_cnt = django_user_model.objects.count()
        valid_data = {
            'email': 'test_email@yamdb.fake',
            'username': 'valid_username_1'
        }
        admin_client.post(self.URL_ADMIN_CREATE_USER, data=valid_data)
        assert (user_cnt + 1) == django_user_model.objects.count(), (
            '≈сли POST-запрос администратора на эндпоинт '
            f'`{self.URL_ADMIN_CREATE_USER}` содержит корректные данные - '
            'должен быть создан новый пользователь.'
        )
    
        response = client.post(self.URL_SIGNUP, data=valid_data)
>       assert response.status_code == HTTPStatus.OK, (
            f'ѕроверьте, что POST-запрос к {self.URL_SIGNUP} с данными '
            'пользовател€, созданного администратором,  возвращает ответ '
            'со статусом 200.'
        )
E       AssertionError: ѕроверьте, что POST-запрос к /api/v1/auth/signup/ с данными пользовател€, созданного администратором,  возвращает ответ со статусом 200.
E       assert 400 == <HTTPStatus.OK: 200>
E         +400
E         -<HTTPStatus.OK: 200>

tests\test_00_user_registration.py:373: AssertionError
------------------------------ Captured log call ------------------------------
WARNING  django.request:log.py:224 Bad Request: /api/v1/auth/signup/
__________________ Test01UserAPI.test_04_02_users_get_search __________________

self = <tests.test_01_users.Test01UserAPI object at 0x0000010FFF998820>
user = <YamdbUser: TestUser>
admin_client = <rest_framework.test.APIClient object at 0x0000010FFF8247C0>
admin = <YamdbUser: TestAdmin>
django_user_model = <class 'users.models.YamdbUser'>

    def test_04_02_users_get_search(self, user, admin_client,
                                    admin, django_user_model):
        search_url = f'{self.USERS_URL}?search={admin.username}'
        response = admin_client.get(search_url)
        assert response.status_code != HTTPStatus.NOT_FOUND, (
            f'Ёндпоинт `{self.USERS_URL}'
            '?search={username}` не найден. ѕроверьте настройки в *urls.py*.'
        )
        reponse_json = response.json()
        assert ('results' in reponse_json
                and isinstance(reponse_json.get('results'), list)), (
            f'ѕроверьте, что GET-запрос к `{self.USERS_URL}'
            '?search={username}` возвращает результаты поиска по значению '
            'ключа `results` в виде списка.'
        )
        users_count = (
            django_user_model.objects.filter(username=admin.username).count()
        )
>       assert len(reponse_json['results']) == users_count, (
            f'ѕроверьте, что GET-запрос к `{self.USERS_URL}'
            '?search={username}` возвращает данные только тех пользователей, '
            '`username` которых удовлетвор€ет условию поиска.'
        )
E       AssertionError: ѕроверьте, что GET-запрос к `/api/v1/users/?search={username}` возвращает данные только тех пользователей, `username` которых удовлетвор€ет условию поиска.
E       assert 2 == 1
E         +2
E         -1

tests\test_01_users.py:117: AssertionError
___________ Test01UserAPI.test_07_05_users_username_put_not_allowed ___________

self = <tests.test_01_users.Test01UserAPI object at 0x0000010FFF99A0D0>
admin_client = <rest_framework.test.APIClient object at 0x0000010FFFA17EB0>
user = <YamdbUser: TestUser>

    def test_07_05_users_username_put_not_allowed(self, admin_client, user):
        response = admin_client.put(
            f'{self.USERS_URL}{user.username}/', data=self.PATCH_DATA
        )
>       assert response.status_code == HTTPStatus.METHOD_NOT_ALLOWED, (
            f'ѕроверьте, что PUT-запрос к `{self.USERS_URL}'
            '{username}/` не предусмотрен и возвращает статус 405.'
        )
E       AssertionError: ѕроверьте, что PUT-запрос к `/api/v1/users/{username}/` не предусмотрен и возвращает статус 405.
E       assert 403 == <HTTPStatus.METHOD_NOT_ALLOWED: 405>
E         +403
E         -<HTTPStatus.METHOD_NOT_ALLOWED: 405>

tests\test_01_users.py:412: AssertionError
------------------------------ Captured log call ------------------------------
WARNING  django.request:log.py:224 Forbidden: /api/v1/users/TestUser/
_____________________ Test01UserAPI.test_09_users_me_get ______________________

self = <tests.test_01_users.Test01UserAPI object at 0x0000010FFF9E11F0>
user_client = <rest_framework.test.APIClient object at 0x0000010FFF9D7D30>
user = <YamdbUser: TestUser>

    def test_09_users_me_get(self, user_client, user):
>       response = user_client.get(f'{self.USERS_ME_URL}')

tests\test_01_users.py:476: 
_ _ _ _ _ _ _ _ _ _ _ _ _ _ _ _ _ _ _ _ _ _ _ _ _ _ _ _ _ _ _ _ _ _ _ _ _ _ _ _
..\.venv\lib\site-packages\rest_framework\test.py:288: in get
    response = super().get(path, data=data, **extra)
..\.venv\lib\site-packages\rest_framework\test.py:205: in get
    return self.generic('GET', path, **r)
..\.venv\lib\site-packages\rest_framework\test.py:233: in generic
    return super().generic(
..\.venv\lib\site-packages\django\test\client.py:473: in generic
    return self.request(**r)
..\.venv\lib\site-packages\rest_framework\test.py:285: in request
    return super().request(**kwargs)
..\.venv\lib\site-packages\rest_framework\test.py:237: in request
    request = super().request(**kwargs)
..\.venv\lib\site-packages\django\test\client.py:719: in request
    self.check_exception(response)
..\.venv\lib\site-packages\django\test\client.py:580: in check_exception
    raise exc_value
..\.venv\lib\site-packages\django\core\handlers\exception.py:47: in inner
    response = get_response(request)
..\.venv\lib\site-packages\django\core\handlers\base.py:181: in _get_response
    response = wrapped_callback(request, *callback_args, **callback_kwargs)
..\.venv\lib\site-packages\django\views\decorators\csrf.py:54: in wrapped_view
    return view_func(*args, **kwargs)
..\.venv\lib\site-packages\rest_framework\viewsets.py:125: in view
    return self.dispatch(request, *args, **kwargs)
..\.venv\lib\site-packages\rest_framework\views.py:509: in dispatch
    response = self.handle_exception(exc)
..\.venv\lib\site-packages\rest_framework\views.py:469: in handle_exception
    self.raise_uncaught_exception(exc)
..\.venv\lib\site-packages\rest_framework\views.py:480: in raise_uncaught_exception
    raise exc
..\.venv\lib\site-packages\rest_framework\views.py:506: in dispatch
    response = handler(request, *args, **kwargs)
..\.venv\lib\site-packages\rest_framework\mixins.py:46: in list
    return Response(serializer.data)
..\.venv\lib\site-packages\rest_framework\serializers.py:745: in data
    ret = super().data
..\.venv\lib\site-packages\rest_framework\serializers.py:246: in data
    self._data = self.to_representation(self.instance)
_ _ _ _ _ _ _ _ _ _ _ _ _ _ _ _ _ _ _ _ _ _ _ _ _ _ _ _ _ _ _ _ _ _ _ _ _ _ _ _

self = SingleUserSerializer(<YamdbUser: TestUser>, context={'request': <rest_framework.request.Request: GET '/api/v1/users/me...oices=(('user', 'ѕользователь'), ('moderator', 'ћодератор'), ('admin', 'јдминистратор')), label='–оль', read_only=True)
data = <YamdbUser: TestUser>

    def to_representation(self, data):
        """
        List of object instances -> List of dicts of primitive datatypes.
        """
        # Dealing with nested relationships, data can be a Manager,
        # so, first get a queryset from the Manager if needed
        iterable = data.all() if isinstance(data, models.Manager) else data
    
>       return [
            self.child.to_representation(item) for item in iterable
        ]
E       TypeError: 'YamdbUser' object is not iterable

..\.venv\lib\site-packages\rest_framework\serializers.py:663: TypeError
------------------------------ Captured log call ------------------------------
ERROR    django.request:log.py:224 Internal Server Error: /api/v1/users/me/
Traceback (most recent call last):
  File "f:\Python\_Dev\api_yamdb\.venv\lib\site-packages\django\core\handlers\exception.py", line 47, in inner
    response = get_response(request)
  File "f:\Python\_Dev\api_yamdb\.venv\lib\site-packages\django\core\handlers\base.py", line 181, in _get_response
    response = wrapped_callback(request, *callback_args, **callback_kwargs)
  File "f:\Python\_Dev\api_yamdb\.venv\lib\site-packages\django\views\decorators\csrf.py", line 54, in wrapped_view
    return view_func(*args, **kwargs)
  File "f:\Python\_Dev\api_yamdb\.venv\lib\site-packages\rest_framework\viewsets.py", line 125, in view
    return self.dispatch(request, *args, **kwargs)
  File "f:\Python\_Dev\api_yamdb\.venv\lib\site-packages\rest_framework\views.py", line 509, in dispatch
    response = self.handle_exception(exc)
  File "f:\Python\_Dev\api_yamdb\.venv\lib\site-packages\rest_framework\views.py", line 469, in handle_exception
    self.raise_uncaught_exception(exc)
  File "f:\Python\_Dev\api_yamdb\.venv\lib\site-packages\rest_framework\views.py", line 480, in raise_uncaught_exception
    raise exc
  File "f:\Python\_Dev\api_yamdb\.venv\lib\site-packages\rest_framework\views.py", line 506, in dispatch
    response = handler(request, *args, **kwargs)
  File "f:\Python\_Dev\api_yamdb\.venv\lib\site-packages\rest_framework\mixins.py", line 46, in list
    return Response(serializer.data)
  File "f:\Python\_Dev\api_yamdb\.venv\lib\site-packages\rest_framework\serializers.py", line 745, in data
    ret = super().data
  File "f:\Python\_Dev\api_yamdb\.venv\lib\site-packages\rest_framework\serializers.py", line 246, in data
    self._data = self.to_representation(self.instance)
  File "f:\Python\_Dev\api_yamdb\.venv\lib\site-packages\rest_framework\serializers.py", line 663, in to_representation
    return [
TypeError: 'YamdbUser' object is not iterable
___________________ Test01UserAPI.test_10_01_users_me_patch ___________________

self = <tests.test_01_users.Test01UserAPI object at 0x0000010FD725B910>
django_user_model = <class 'users.models.YamdbUser'>
admin_client = <rest_framework.test.APIClient object at 0x0000010FD730E4F0>
admin = <YamdbUser: TestAdmin>
moderator_client = <rest_framework.test.APIClient object at 0x0000010FD730E850>
moderator = <YamdbUser: TestModerator>
user_client = <rest_framework.test.APIClient object at 0x0000010FD730E5B0>
user = <YamdbUser: TestAdmin>

    def test_10_01_users_me_patch(self, django_user_model, admin_client,
                                  admin, moderator_client, moderator,
                                  user_client, user):
        data = {'bio': 'description'}
    
        for client, user in (
                (admin_client, admin),
                (moderator_client, moderator),
                (user_client, user)
        ):
            response = client.patch(f'{self.USERS_ME_URL}', data=data)
>           assert response.status_code == HTTPStatus.OK, (
                'ѕроверьте, что PATCH-запрос к '
                f'`{self.USERS_ME_URL}` доступен пользовател€м всех '
                'ролей и возвращает ответ со статусом 200.'
            )
E           AssertionError: ѕроверьте, что PATCH-запрос к `/api/v1/users/me/` доступен пользовател€м всех ролей и возвращает ответ со статусом 200.
E           assert 405 == <HTTPStatus.OK: 200>
E             +405
E             -<HTTPStatus.OK: 200>

tests\test_01_users.py:518: AssertionError
------------------------------ Captured log call ------------------------------
WARNING  django.request:log.py:224 Method Not Allowed: /api/v1/users/me/
___ Test01UserAPI.test_10_02_users_me_has_field_validation[data0-messege0] ____

self = <tests.test_01_users.Test01UserAPI object at 0x0000010FD730E670>
user_client = <rest_framework.test.APIClient object at 0x0000010FD7350820>
data = {'email': 'aaaaaaaaaaaaaaaaaaaaaaaaaaaaaaaaaaaaaaaaaaaaaaaaaaaaaaaaaaaaaaaaaaaaaaaaaaaaaaaaaaaaaaaaaaaaaaaaaaaaaaaaaaa...aaaaaaaaaaaaaaaaaaaaaaaaaaaaaaaaaaaaaaaaaaaaaaaaaaaaaaaaaaaaaaaaaaaaaaaaaaaa@yamdb.fake', 'username': 'valid-username'}
messege = ('ѕроверьте, что при обработке {request_method}-запроса к `{url}` провер€етс€ длина пол€ `email`: его содержимое не должно быть длиннее 254 символа.',)

    @pytest.mark.parametrize(
        'data,messege', invalid_data_for_user_patch_and_creation
    )
    def test_10_02_users_me_has_field_validation(self, user_client, data,
                                                 messege):
        request_method = 'PATCH'
        response = user_client.patch(self.USERS_ME_URL, data=data)
>       assert response.status_code == HTTPStatus.BAD_REQUEST, (
            messege[0].format(
                url=self.USERS_ME_URL,
                request_method=request_method
            )
        )
E       AssertionError: ѕроверьте, что при обработке PATCH-запроса к `/api/v1/users/me/` провер€етс€ длина пол€ `email`: его содержимое не должно быть длиннее 254 символа.
E       assert 405 == <HTTPStatus.BAD_REQUEST: 400>
E         +405
E         -<HTTPStatus.BAD_REQUEST: 400>

tests\test_01_users.py:538: AssertionError
------------------------------ Captured log call ------------------------------
WARNING  django.request:log.py:224 Method Not Allowed: /api/v1/users/me/
___ Test01UserAPI.test_10_02_users_me_has_field_validation[data1-messege1] ____

self = <tests.test_01_users.Test01UserAPI object at 0x0000010FFFE2B5B0>
user_client = <rest_framework.test.APIClient object at 0x0000010FD73036D0>
data = {'email': 'valid-email@yamdb.fake', 'username': 'aaaaaaaaaaaaaaaaaaaaaaaaaaaaaaaaaaaaaaaaaaaaaaaaaaaaaaaaaaaaaaaaaaaaaaaaaaaaaaaaaaaaaaaaaaaaaaaaaaaaaaaaaaaaaaaaaaaaaaaaaaaaaaaaaaaaaaaaaaaaaaaaaaaaaaa'}
messege = ('ѕроверьте, что при обработке {request_method}-запроса к `{url}` провер€етс€ длина пол€ `username`: его содержимое не должно быть длиннее 150 символов.',)

    @pytest.mark.parametrize(
        'data,messege', invalid_data_for_user_patch_and_creation
    )
    def test_10_02_users_me_has_field_validation(self, user_client, data,
                                                 messege):
        request_method = 'PATCH'
        response = user_client.patch(self.USERS_ME_URL, data=data)
>       assert response.status_code == HTTPStatus.BAD_REQUEST, (
            messege[0].format(
                url=self.USERS_ME_URL,
                request_method=request_method
            )
        )
E       AssertionError: ѕроверьте, что при обработке PATCH-запроса к `/api/v1/users/me/` провер€етс€ длина пол€ `username`: его содержимое не должно быть длиннее 150 символов.
E       assert 405 == <HTTPStatus.BAD_REQUEST: 400>
E         +405
E         -<HTTPStatus.BAD_REQUEST: 400>

tests\test_01_users.py:538: AssertionError
------------------------------ Captured log call ------------------------------
WARNING  django.request:log.py:224 Method Not Allowed: /api/v1/users/me/
___ Test01UserAPI.test_10_02_users_me_has_field_validation[data2-messege2] ____

self = <tests.test_01_users.Test01UserAPI object at 0x0000010FD7303C10>
user_client = <rest_framework.test.APIClient object at 0x0000010FFF8B47F0>
data = {'email': 'valid-email@yamdb.fake', 'username': '|-|aTa|_|_|a'}
messege = ('ѕроверьте, что при обработке {request_method}-запроса к `{url}` содержание пол€ `username` провер€етс€ на соответствие паттерну, указанному в спецификации: ^[\\w.@+-]+\\Z',)

    @pytest.mark.parametrize(
        'data,messege', invalid_data_for_user_patch_and_creation
    )
    def test_10_02_users_me_has_field_validation(self, user_client, data,
                                                 messege):
        request_method = 'PATCH'
        response = user_client.patch(self.USERS_ME_URL, data=data)
>       assert response.status_code == HTTPStatus.BAD_REQUEST, (
            messege[0].format(
                url=self.USERS_ME_URL,
                request_method=request_method
            )
        )
E       AssertionError: ѕроверьте, что при обработке PATCH-запроса к `/api/v1/users/me/` содержание пол€ `username` провер€етс€ на соответствие паттерну, указанному в спецификации: ^[\w.@+-]+\Z
E       assert 405 == <HTTPStatus.BAD_REQUEST: 400>
E         +405
E         -<HTTPStatus.BAD_REQUEST: 400>

tests\test_01_users.py:538: AssertionError
------------------------------ Captured log call ------------------------------
WARNING  django.request:log.py:224 Method Not Allowed: /api/v1/users/me/
___ Test01UserAPI.test_10_02_users_me_has_field_validation[data3-messege3] ____

self = <tests.test_01_users.Test01UserAPI object at 0x0000010FD737E100>
user_client = <rest_framework.test.APIClient object at 0x0000010FD7396310>
data = {'email': 'valid-email@yamdb.fake', 'first_name': 'toolonggggggggggggggggggggggggggggggggggggggggggggggggggggggggggggggggggggggggggggggggggggggggggggggggggggggggggggggggggggggggggggggggggggggggggggggggg', 'username': 'validname'}
messege = ('ѕроверьте, что при обработке POST-запроса к `{url}` провер€етс€ длина пол€ `first_name`: его содержимое не должно быть длиннее 150 символов.',)

    @pytest.mark.parametrize(
        'data,messege', invalid_data_for_user_patch_and_creation
    )
    def test_10_02_users_me_has_field_validation(self, user_client, data,
                                                 messege):
        request_method = 'PATCH'
        response = user_client.patch(self.USERS_ME_URL, data=data)
>       assert response.status_code == HTTPStatus.BAD_REQUEST, (
            messege[0].format(
                url=self.USERS_ME_URL,
                request_method=request_method
            )
        )
E       AssertionError: ѕроверьте, что при обработке POST-запроса к `/api/v1/users/me/` провер€етс€ длина пол€ `first_name`: его содержимое не должно быть длиннее 150 символов.
E       assert 405 == <HTTPStatus.BAD_REQUEST: 400>
E         +405
E         -<HTTPStatus.BAD_REQUEST: 400>

tests\test_01_users.py:538: AssertionError
------------------------------ Captured log call ------------------------------
WARNING  django.request:log.py:224 Method Not Allowed: /api/v1/users/me/
___ Test01UserAPI.test_10_02_users_me_has_field_validation[data4-messege4] ____

self = <tests.test_01_users.Test01UserAPI object at 0x0000010FD731BEB0>
user_client = <rest_framework.test.APIClient object at 0x0000010FFF911E20>
data = {'email': 'valid-email@yamdb.fake', 'last_name': 'toolonggggggggggggggggggggggggggggggggggggggggggggggggggggggggggggggggggggggggggggggggggggggggggggggggggggggggggggggggggggggggggggggggggggggggggggggggg', 'username': 'validname'}
messege = ('ѕроверьте, что при обработке POST-запроса к `{url}` провер€етс€ длина пол€ `last_name`: его содержимое не должно быть длиннее 150 символов.',)

    @pytest.mark.parametrize(
        'data,messege', invalid_data_for_user_patch_and_creation
    )
    def test_10_02_users_me_has_field_validation(self, user_client, data,
                                                 messege):
        request_method = 'PATCH'
        response = user_client.patch(self.USERS_ME_URL, data=data)
>       assert response.status_code == HTTPStatus.BAD_REQUEST, (
            messege[0].format(
                url=self.USERS_ME_URL,
                request_method=request_method
            )
        )
E       AssertionError: ѕроверьте, что при обработке POST-запроса к `/api/v1/users/me/` провер€етс€ длина пол€ `last_name`: его содержимое не должно быть длиннее 150 символов.
E       assert 405 == <HTTPStatus.BAD_REQUEST: 400>
E         +405
E         -<HTTPStatus.BAD_REQUEST: 400>

tests\test_01_users.py:538: AssertionError
------------------------------ Captured log call ------------------------------
WARNING  django.request:log.py:224 Method Not Allowed: /api/v1/users/me/
_______ Test01UserAPI.test_10_03_users_me_patch_change_role_not_allowed _______

self = <tests.test_01_users.Test01UserAPI object at 0x0000010FD7396D60>
user_client = <rest_framework.test.APIClient object at 0x0000010FD72914F0>
user = <YamdbUser: TestUser>
django_user_model = <class 'users.models.YamdbUser'>

    def test_10_03_users_me_patch_change_role_not_allowed(self,
                                                          user_client,
                                                          user,
                                                          django_user_model):
        response = user_client.patch(
            f'{self.USERS_ME_URL}', data=self.PATCH_DATA
        )
>       assert response.status_code == HTTPStatus.OK, (
            'ѕроверьте, что PATCH-запрос пользовател€ с ролью `user` к '
            f'`{self.USERS_ME_URL}` возвращает ответ со статусом 200.'
        )
E       AssertionError: ѕроверьте, что PATCH-запрос пользовател€ с ролью `user` к `/api/v1/users/me/` возвращает ответ со статусом 200.
E       assert 405 == <HTTPStatus.OK: 200>
E         +405
E         -<HTTPStatus.OK: 200>

tests\test_01_users.py:552: AssertionError
------------------------------ Captured log call ------------------------------
WARNING  django.request:log.py:224 Method Not Allowed: /api/v1/users/me/
_______________ Test02CategoryAPI.test_04_category_delete_admin _______________

self = <tests.test_02_category.Test02CategoryAPI object at 0x0000010FFF8F53A0>
admin_client = <rest_framework.test.APIClient object at 0x0000010FFFCCDB20>

    def test_04_category_delete_admin(self, admin_client):
        category_1, category_2 = create_categories(admin_client)
        response = admin_client.delete(
            self.CATEGORY_SLUG_TEMPLATE_URL.format(
                slug=category_1['slug']
            )
        )
        assert response.status_code == HTTPStatus.NO_CONTENT, (
            'ѕроверьте, что DELETE-запрос администратора к '
            f'`{self.CATEGORY_SLUG_TEMPLATE_URL}` возвращает ответ со '
            'статусом 204.'
        )
        response = admin_client.get(self.CATEGORY_URL)
        test_data = response.json()['results']
        assert len(test_data) == 1, (
            'ѕроверьте, что DELETE-запрос администратора к '
            f'`{self.CATEGORY_SLUG_TEMPLATE_URL}` удал€ет категорию.'
        )
    
        response = admin_client.get(
            self.CATEGORY_SLUG_TEMPLATE_URL.format(
                slug=category_2['slug']
            )
        )
>       assert response.status_code == HTTPStatus.METHOD_NOT_ALLOWED, (
            'ѕроверьте, что GET-запросы к '
            f'`{self.CATEGORY_SLUG_TEMPLATE_URL}` запрещены и возвращают '
            'ответ со статусом 405.'
        )
E       AssertionError: ѕроверьте, что GET-запросы к `/api/v1/categories/{slug}/` запрещены и возвращают ответ со статусом 405.
E       assert 200 == <HTTPStatus.METHOD_NOT_ALLOWED: 405>
E         +200
E         -<HTTPStatus.METHOD_NOT_ALLOWED: 405>

tests\test_02_category.py:123: AssertionError
____________________ Test03GenreAPI.test_04_genres_delete _____________________

self = <tests.test_03_genre.Test03GenreAPI object at 0x0000010FFFA25760>
admin_client = <rest_framework.test.APIClient object at 0x0000010FFF9EF7F0>

    def test_04_genres_delete(self, admin_client):
        genres = create_genre(admin_client)
        response = admin_client.delete(
            self.GENRES_SLUG_TEMPLATE_URL.format(slug=genres[0]['slug'])
        )
        assert response.status_code == HTTPStatus.NO_CONTENT, (
            'ѕроверьте, что DELETE-запрос администратора к '
            f'`{self.GENRES_SLUG_TEMPLATE_URL}` возвращает ответ со  статусом '
            '204.'
        )
        response = admin_client.get(self.GENRES_URL)
        test_data = response.json()['results']
        assert len(test_data) == len(genres) - 1, (
            'ѕроверьте, что DELETE-запрос администратора к '
            f'`{self.GENRES_SLUG_TEMPLATE_URL}` удал€ет жанр из Ѕƒ.'
        )
        response = admin_client.get(
            self.GENRES_SLUG_TEMPLATE_URL.format(slug=genres[0]['slug'])
        )
>       assert response.status_code == HTTPStatus.METHOD_NOT_ALLOWED, (
            'ѕроверьте, что GET-запрос администратора к '
            f'`{self.GENRES_SLUG_TEMPLATE_URL}` возвращает ответ со статусом '
            '405.'
        )
E       AssertionError: ѕроверьте, что GET-запрос администратора к `/api/v1/genres/{slug}/` возвращает ответ со статусом 405.
E       assert 404 == <HTTPStatus.METHOD_NOT_ALLOWED: 405>
E         +404
E         -<HTTPStatus.METHOD_NOT_ALLOWED: 405>

tests\test_03_genre.py:108: AssertionError
------------------------------ Captured log call ------------------------------
WARNING  django.request:log.py:224 Not Found: /api/v1/genres/horror/
_____________________ Test04TitleAPI.test_02_title_admin ______________________

self = <tests.test_04_title.Test04TitleAPI object at 0x0000010FFF99AF40>
admin_client = <rest_framework.test.APIClient object at 0x0000010FFF9EB760>
client = <django.test.client.Client object at 0x0000010FFFC315E0>

    def test_02_title_admin(self, admin_client, client):
        genres = create_genre(admin_client)
        categories = create_categories(admin_client)
        title_count = 0
    
        assert_msg = (
            f'≈сли POST-запрос администратора к `{self.TITLES_URL}` '
            'содержит некорректные данные - должен вернутьс€ ответ со '
            'статусом 400.'
        )
        data = {}
        response = admin_client.post(self.TITLES_URL, data=data)
        assert response.status_code == HTTPStatus.BAD_REQUEST, assert_msg
    
        invalid_data = {
            'name': '”гнать за 60 секунд',
            'year': 'дветыщи',
            'genre': [genres[1]['slug']],
            'category': categories[1]['slug'],
            'description': '”гон€л машины всю ночь и немного подустал.'
        }
        response = admin_client.post(self.TITLES_URL, data=invalid_data)
        assert response.status_code == HTTPStatus.BAD_REQUEST, assert_msg
    
        post_data_1 = {
            'name': 'ћост через реку  вай',
            'year': 1957,
            'genre': [genres[0]['slug'], genres[1]['slug']],
            'category': categories[0]['slug'],
            'description': '–он —вонсон рекомендует.'
        }
        response = admin_client.post(self.TITLES_URL, data=post_data_1)
        assert response.status_code == HTTPStatus.CREATED, (
            f'≈сли POST-запрос администратора к `{self.TITLES_URL}` '
            'содержит корректные данные - должен вернутьс€ ответ со статусом '
            '201.'
        )
        title_count += 1
    
        post_data_2 = {
            'name': '’ороший, плохой, злой.',
            'year': 1966,
            'genre': [genres[2]['slug']],
            'category': categories[1]['slug'],
            'description': '”гадай ревьюера по названию фильма.'
        }
        response = admin_client.post(self.TITLES_URL, data=post_data_2)
        assert response.status_code == HTTPStatus.CREATED, (
            f'≈сли POST-запрос администратора к `{self.TITLES_URL}` '
            'содержит корректные данные - должен вернутьс€ ответ со статусом '
            '201.'
        )
        title_count += 1
        assert isinstance(response.json().get('id'), int), (
            'ѕроверьте, при POST-запросе администратора к '
            f'`{self.TITLES_URL}` в ответе возвращаютс€ данные созданного '
            'объекта. —ейчас поле `id` отсутствует или не €вл€етс€ целым '
            'числом.'
        )
    
        response = client.get(self.TITLES_URL)
        assert response.status_code == HTTPStatus.OK, (
            'ѕроверьте, что GET-запрос неавторизованного пользовател€ к '
            f'`{self.TITLES_URL}` возвращает ответ со статусом 200.'
        )
        data = response.json()
        check_pagination(self.TITLES_URL, data, title_count)
    
        expected_title_names = {post_data_1['name'], post_data_2['name']}
        title_names = {element.get('name') for element in data['results']}
        assert len(expected_title_names.intersection(title_names)) == 2, (
            f'ѕроверьте, что дл€ эндпоинта `{self.TITLES_URL}` настроена '
            'пагинаци€. —ейчас значение параметра `results` отсутствует или '
            'содержит некорректную информацию о существующих объектах.'
        )
    
        for element in data['results']:
            if element['name'] == post_data_1['name']:
                title = element
    
        assert title.get('rating') is None, (
            'ѕроверьте, что при GET-запросе неавторизованного '
            f'пользовател€ к `{self.TITLES_URL}` возвращаетс€ информаци€ о '
            'рейтинге произведений. ≈сли отзывов о произведении нет - '
            'значением пол€ `rating` должено быть `None`.'
        )
        assert title.get('category') == categories[0], (
            'ѕроверьте, что при GET-запросе неавторизованного пользовател€ к '
            f'`{self.TITLES_URL}` в ответе содержитс€ информаци€ о категори€х '
            'произведений. —ейчас поле `category` дл€ элементов списка '
            '`results` отсутствует или содержит некорректное значение.'
        )
    
        title_genres = title.get('genre', [])
        assert genres[0] in title_genres and genres[1] in title_genres, (
            'ѕроверьте, что при GET-запросе неавторизованного пользовател€ к '
            f'`{self.TITLES_URL}` в ответе содержитс€ список жанров дл€ '
            'каждого произведени€. —ейчас поле `genres` дл€ элементов списка '
            '`results` отсутствует или содержит некорректное значение.'
        )
        assert title.get('year') == post_data_1['year'], (
            'ѕроверьте, что при GET-запросе неавторизованного пользовател€ к '
            f'`{self.TITLES_URL}` в ответе содержитс€ год выхода '
            'произведений. —ейчас поле `year` дл€ элементов списка `results` '
            'отсутствует или содержит некорректное значение.'
        )
        assert title.get('description') == post_data_1['description'], (
            'ѕроверьте, что при GET-запросе неавторизованного пользовател€ к '
            f'`{self.TITLES_URL}` в ответе содержатс€ описани€ произведений. '
            '—ейчас поле `description` дл€ элементов списка `results` '
            'отсутствует или содержит некорректное значение.'
        )
    
        assert isinstance(title.get('id'), int), (
            'ѕроверьте, что при GET-запросе неавторизованного пользовател€ к '
            f'`{self.TITLES_URL}` в ответе содержатс€ `id` произведений. '
            '—ейчас поле `id` дл€ элементов списка `results` отсутствует или '
            'его значение не €вл€етс€ целым числом.'
        )
    
        data = {
            'name': '“итаник',
            'year': 1997,
            'genre': [genres[1]['slug']],
            'category': categories[1]['slug'],
            'description': 'ƒверь выдержала бы и двоих...'
        }
        admin_client.post(self.TITLES_URL, data=data)
    
        response = admin_client.get(
            f'{self.TITLES_URL}?genre={genres[1]["slug"]}'
        )
        data = response.json()
>       assert len(data['results']) == 2, (
            f'ѕроверьте, что дл€ эндпоинта `{self.TITLES_URL}` реализована '
            'возможность фильтрации по полю `genre` с использованием '
            'параметра `slug` жанра.'
        )
E       AssertionError: ѕроверьте, что дл€ эндпоинта `/api/v1/titles/` реализована возможность фильтрации по полю `genre` с использованием параметра `slug` жанра.
E       assert 3 == 2
E         +3
E         -2

tests\test_04_title.py:161: AssertionError
------------------------------ Captured log call ------------------------------
WARNING  django.request:log.py:224 Bad Request: /api/v1/titles/
WARNING  django.request:log.py:224 Bad Request: /api/v1/titles/
_____________________ Test05ReviewAPI.test_02_review_post _____________________

self = <tests.test_05_review.Test05ReviewAPI object at 0x0000010FFF7E7070>
admin_client = <rest_framework.test.APIClient object at 0x0000010FFFC9F1F0>
user_client = <rest_framework.test.APIClient object at 0x0000010FFFCADD30>
moderator_client = <rest_framework.test.APIClient object at 0x0000010FFFCAD8E0>
admin = <YamdbUser: TestAdmin>

    def test_02_review_post(self, admin_client, user_client,
                            moderator_client, admin):
        titles, _, _ = create_titles(admin_client)
        title_0_reviews_count = 0
        first_title_reviews_url = self.REVIEWS_URL_TEMPLATE.format(
            title_id=titles[0]['id']
        )
        second_title_reviews_url = self.REVIEWS_URL_TEMPLATE.format(
            title_id=titles[1]['id']
        )
    
        data = {}
        response = user_client.post(first_title_reviews_url, data=data)
        assert response.status_code == HTTPStatus.BAD_REQUEST, (
            '≈сли POST-запрос авторизованного пользовател€ к '
            f'`{self.REVIEWS_URL_TEMPLATE}` содержит некорректные данные - '
            'должен вернутьс€ ответ со статусом 400.'
        )
    
        post_data = {
            'text': 'Ќеочень',
            'score': 5
        }
        create_single_review(
            admin_client,
            titles[0]['id'],
            post_data['text'],
            post_data['score']
        )
        title_0_reviews_count += 1
    
        data = {
            'text': 'Ўл€па',
            'score': 1
        }
        response = admin_client.post(first_title_reviews_url, data=data)
>       assert response.status_code == HTTPStatus.BAD_REQUEST, (
            'ѕроверьте, что при попытке пользовател€ создать второй отзыв на '
            'одно и то же произведение POST-запрос к '
            f'`{self.REVIEWS_URL_TEMPLATE}` вернЄт ответ со статусом 400.'
        )
E       AssertionError: ѕроверьте, что при попытке пользовател€ создать второй отзыв на одно и то же произведение POST-запрос к `/api/v1/titles/{title_id}/reviews/` вернЄт ответ со статусом 400.
E       assert 201 == <HTTPStatus.BAD_REQUEST: 400>
E         +201
E         -<HTTPStatus.BAD_REQUEST: 400>

tests\test_05_review.py:111: AssertionError
------------------------------ Captured log call ------------------------------
WARNING  django.request:log.py:224 Bad Request: /api/v1/titles/13/reviews/
__________________ Test05ReviewAPI.test_03_review_detail_get __________________

self = <tests.test_05_review.Test05ReviewAPI object at 0x0000010FFF828670>
client = <django.test.client.Client object at 0x0000010FD7291460>
admin_client = <rest_framework.test.APIClient object at 0x0000010FFF8DDDF0>
admin = <YamdbUser: TestAdmin>, user = <YamdbUser: TestUser>
user_client = <rest_framework.test.APIClient object at 0x0000010FFFCB40A0>
moderator = <YamdbUser: TestModerator>
moderator_client = <rest_framework.test.APIClient object at 0x0000010FD736B0D0>

    def test_03_review_detail_get(self, client, admin_client, admin, user,
                                  user_client, moderator, moderator_client):
        author_map = {
            admin: admin_client,
            user: user_client,
            moderator: moderator_client
        }
        reviews, titles = create_reviews(admin_client, author_map)
    
        response = client.get(
            self.REVIEW_DETAIL_URL_TEMPLATE.format(
                title_id=titles[0]['id'], review_id=reviews[0]['id']
            )
        )
        assert response.status_code != HTTPStatus.NOT_FOUND, (
            f'Ёндпоинт `{self.REVIEW_DETAIL_URL_TEMPLATE}` не найден. '
            'ѕроверьте настройки в *urls.py*.'
        )
>       assert response.status_code == HTTPStatus.OK, (
            'ѕроверьте, что GET-запрос неавторизованного пользовател€ к '
            f'`{self.REVIEW_DETAIL_URL_TEMPLATE}` возвращает ответ со '
            'статусом 200.'
        )
E       AssertionError: ѕроверьте, что GET-запрос неавторизованного пользовател€ к `/api/v1/titles/{title_id}/reviews/{review_id}/` возвращает ответ со статусом 200.
E       assert 401 == <HTTPStatus.OK: 200>
E         +401
E         -<HTTPStatus.OK: 200>

tests\test_05_review.py:244: AssertionError
------------------------------ Captured log call ------------------------------
WARNING  django.request:log.py:224 Unauthorized: /api/v1/titles/15/reviews/6/
__________________ Test06CommentAPI.test_01_comment_not_auth __________________

self = <tests.test_06_comment.Test06CommentAPI object at 0x0000010FFF804370>
client = <django.test.client.Client object at 0x0000010FFFC6F070>
admin_client = <rest_framework.test.APIClient object at 0x0000010FD72E2610>
admin = <YamdbUser: TestAdmin>
user_client = <rest_framework.test.APIClient object at 0x0000010FFFCF0C70>
user = <YamdbUser: TestUser>
moderator_client = <rest_framework.test.APIClient object at 0x0000010FD72AD2E0>
moderator = <YamdbUser: TestModerator>

    def test_01_comment_not_auth(self, client, admin_client, admin,
                                 user_client, user, moderator_client,
                                 moderator):
        author_map = {
            admin: admin_client,
            user: user_client,
            moderator: moderator_client
        }
        reviews, titles = create_reviews(admin_client, author_map)
    
        response = client.get(
            self.COMMENTS_URL_TEMPLATE.format(
                title_id=titles[0]['id'],
                review_id=reviews[0]['id']
            )
        )
>       assert response.status_code != HTTPStatus.NOT_FOUND, (
            f'Ёндпоинт `{self.COMMENTS_URL_TEMPLATE}` не найден. ѕроверьте '
            'настрокий в *urls.py*.'
        )
E       AssertionError: Ёндпоинт `/api/v1/titles/{title_id}/reviews/{review_id}/comments/` не найден. ѕроверьте настрокий в *urls.py*.
E       assert 404 != <HTTPStatus.NOT_FOUND: 404>
E        +  where 404 = <HttpResponseNotFound status_code=404, "text/html">.status_code
E        +  and   <HTTPStatus.NOT_FOUND: 404> = HTTPStatus.NOT_FOUND

tests\test_06_comment.py:34: AssertionError
------------------------------ Captured log call ------------------------------
WARNING  django.request:log.py:224 Not Found: /api/v1/titles/23/reviews/18/comments/
______________________ Test06CommentAPI.test_02_comment _______________________

self = <tests.test_06_comment.Test06CommentAPI object at 0x0000010FFFD92580>
admin_client = <rest_framework.test.APIClient object at 0x0000010FFFA559A0>
admin = <YamdbUser: TestAdmin>
user_client = <rest_framework.test.APIClient object at 0x0000010FFFAB8070>
user = <YamdbUser: TestUser>
moderator_client = <rest_framework.test.APIClient object at 0x0000010FFFAB87F0>
moderator = <YamdbUser: TestModerator>

    def test_02_comment(self, admin_client, admin, user_client, user,
                        moderator_client, moderator):
        author_map = {
            admin: admin_client,
            user: user_client,
            moderator: moderator_client
        }
        reviews, titles = create_reviews(admin_client, author_map)
        first_review_comment_cnt = 0
    
        data = {}
        response = user_client.post(
            self.COMMENTS_URL_TEMPLATE.format(
                title_id=titles[0]['id'],
                review_id=reviews[0]['id']
            ),
            data=data
        )
>       assert response.status_code == HTTPStatus.BAD_REQUEST, (
            '≈сли POST-запрос пользовател€ с ролью `user` к '
            f'`{self.COMMENTS_URL_TEMPLATE}` содержит некорректные данные - '
            'должен вернутьс€ ответ со статусом 400.'
        )
E       AssertionError: ≈сли POST-запрос пользовател€ с ролью `user` к `/api/v1/titles/{title_id}/reviews/{review_id}/comments/` содержит некорректные данные - должен вернутьс€ ответ со статусом 400.
E       assert 404 == <HTTPStatus.BAD_REQUEST: 400>
E         +404
E         -<HTTPStatus.BAD_REQUEST: 400>

tests\test_06_comment.py:61: AssertionError
------------------------------ Captured log call ------------------------------
WARNING  django.request:log.py:224 Not Found: /api/v1/titles/25/reviews/21/comments/
_________________ Test06CommentAPI.test_03_comment_detail_get _________________

self = <tests.test_06_comment.Test06CommentAPI object at 0x0000010FFFA55610>
client = <django.test.client.Client object at 0x0000010FFFCB27F0>
admin_client = <rest_framework.test.APIClient object at 0x0000010FFF9001C0>
admin = <YamdbUser: TestAdmin>
user_client = <rest_framework.test.APIClient object at 0x0000010FFF9008E0>
user = <YamdbUser: TestUser>
moderator_client = <rest_framework.test.APIClient object at 0x0000010FD737E670>
moderator = <YamdbUser: TestModerator>

    def test_03_comment_detail_get(self, client, admin_client, admin,
                                   user_client, user, moderator_client,
                                   moderator):
        author_map = {
            admin: admin_client,
            user: user_client,
            moderator: moderator_client
        }
>       comments, reviews, titles = create_comments(admin_client, author_map)

tests\test_06_comment.py:138: 
_ _ _ _ _ _ _ _ _ _ _ _ _ _ _ _ _ _ _ _ _ _ _ _ _ _ _ _ _ _ _ _ _ _ _ _ _ _ _ _
tests\utils.py:271: in create_comments
    response = create_single_comment(
_ _ _ _ _ _ _ _ _ _ _ _ _ _ _ _ _ _ _ _ _ _ _ _ _ _ _ _ _ _ _ _ _ _ _ _ _ _ _ _

client = <rest_framework.test.APIClient object at 0x0000010FFF9001C0>
title_id = 27, review_id = 24, text = 'comment number 1'

    def create_single_comment(client, title_id, review_id, text):
        data = {'text': text}
        response = client.post(
            f'/api/v1/titles/{title_id}/reviews/{review_id}/comments/',
            data=data
        )
>       assert response.status_code == HTTPStatus.CREATED, (
            '≈сли POST-запрос авторизованного пользовател€ к '
            '`/api/v1/titles/{title_id}/reviews/{review_id}/comments/` содержит '
            'корректные данные - должен вернутьс€ ответ со статусом 201.'
        )
E       AssertionError: ≈сли POST-запрос авторизованного пользовател€ к `/api/v1/titles/{title_id}/reviews/{review_id}/comments/` содержит корректные данные - должен вернутьс€ ответ со статусом 201.

tests\utils.py:172: AssertionError
------------------------------ Captured log call ------------------------------
WARNING  django.request:log.py:224 Not Found: /api/v1/titles/27/reviews/24/comments/
_________ Test06CommentAPI.test_04_comment_detail__user_patch_delete __________

self = <tests.test_06_comment.Test06CommentAPI object at 0x0000010FFFAB0730>
admin_client = <rest_framework.test.APIClient object at 0x0000010FFFAC2FA0>
admin = <YamdbUser: TestAdmin>
user_client = <rest_framework.test.APIClient object at 0x0000010FD71F9100>
user = <YamdbUser: TestUser>
moderator_client = <rest_framework.test.APIClient object at 0x0000010FFFE2B070>
moderator = <YamdbUser: TestModerator>

    def test_04_comment_detail__user_patch_delete(self, admin_client, admin,
                                                  user_client, user,
                                                  moderator_client,
                                                  moderator):
        author_map = {
            admin: admin_client,
            user: user_client,
            moderator: moderator_client
        }
>       comments, reviews, titles = create_comments(admin_client, author_map)

tests\test_06_comment.py:175: 
_ _ _ _ _ _ _ _ _ _ _ _ _ _ _ _ _ _ _ _ _ _ _ _ _ _ _ _ _ _ _ _ _ _ _ _ _ _ _ _
tests\utils.py:271: in create_comments
    response = create_single_comment(
_ _ _ _ _ _ _ _ _ _ _ _ _ _ _ _ _ _ _ _ _ _ _ _ _ _ _ _ _ _ _ _ _ _ _ _ _ _ _ _

client = <rest_framework.test.APIClient object at 0x0000010FFFAC2FA0>
title_id = 29, review_id = 27, text = 'comment number 1'

    def create_single_comment(client, title_id, review_id, text):
        data = {'text': text}
        response = client.post(
            f'/api/v1/titles/{title_id}/reviews/{review_id}/comments/',
            data=data
        )
>       assert response.status_code == HTTPStatus.CREATED, (
            '≈сли POST-запрос авторизованного пользовател€ к '
            '`/api/v1/titles/{title_id}/reviews/{review_id}/comments/` содержит '
            'корректные данные - должен вернутьс€ ответ со статусом 201.'
        )
E       AssertionError: ≈сли POST-запрос авторизованного пользовател€ к `/api/v1/titles/{title_id}/reviews/{review_id}/comments/` содержит корректные данные - должен вернутьс€ ответ со статусом 201.

tests\utils.py:172: AssertionError
------------------------------ Captured log call ------------------------------
WARNING  django.request:log.py:224 Not Found: /api/v1/titles/29/reviews/27/comments/
_________ Test06CommentAPI.test_05_comment_detail_admin_and_moderator _________

self = <tests.test_06_comment.Test06CommentAPI object at 0x0000010FFFAC2610>
admin_client = <rest_framework.test.APIClient object at 0x0000010FD735C760>
admin = <YamdbUser: TestAdmin>
user_client = <rest_framework.test.APIClient object at 0x0000010FFF998100>
user = <YamdbUser: TestUser>
moderator_client = <rest_framework.test.APIClient object at 0x0000010FFF998850>
moderator = <YamdbUser: TestModerator>

    def test_05_comment_detail_admin_and_moderator(self, admin_client, admin,
                                                   user_client, user,
                                                   moderator_client,
                                                   moderator):
        author_map = {
            admin: admin_client,
            user: user_client,
            moderator: moderator_client
        }
>       comments, reviews, titles = create_comments(admin_client, author_map)

tests\test_06_comment.py:254: 
_ _ _ _ _ _ _ _ _ _ _ _ _ _ _ _ _ _ _ _ _ _ _ _ _ _ _ _ _ _ _ _ _ _ _ _ _ _ _ _
tests\utils.py:271: in create_comments
    response = create_single_comment(
_ _ _ _ _ _ _ _ _ _ _ _ _ _ _ _ _ _ _ _ _ _ _ _ _ _ _ _ _ _ _ _ _ _ _ _ _ _ _ _

client = <rest_framework.test.APIClient object at 0x0000010FD735C760>
title_id = 31, review_id = 30, text = 'comment number 1'

    def create_single_comment(client, title_id, review_id, text):
        data = {'text': text}
        response = client.post(
            f'/api/v1/titles/{title_id}/reviews/{review_id}/comments/',
            data=data
        )
>       assert response.status_code == HTTPStatus.CREATED, (
            '≈сли POST-запрос авторизованного пользовател€ к '
            '`/api/v1/titles/{title_id}/reviews/{review_id}/comments/` содержит '
            'корректные данные - должен вернутьс€ ответ со статусом 201.'
        )
E       AssertionError: ≈сли POST-запрос авторизованного пользовател€ к `/api/v1/titles/{title_id}/reviews/{review_id}/comments/` содержит корректные данные - должен вернутьс€ ответ со статусом 201.

tests\utils.py:172: AssertionError
------------------------------ Captured log call ------------------------------
WARNING  django.request:log.py:224 Not Found: /api/v1/titles/31/reviews/30/comments/
______________ Test06CommentAPI.test_06_comment_detail_not_auth _______________

self = <tests.test_06_comment.Test06CommentAPI object at 0x0000010FFFBF0070>
admin_client = <rest_framework.test.APIClient object at 0x0000010FFF9D7B80>
admin = <YamdbUser: TestAdmin>
client = <django.test.client.Client object at 0x0000010FFF9D7310>
user_client = <rest_framework.test.APIClient object at 0x0000010FFF8AB9D0>
user = <YamdbUser: TestUser>
moderator_client = <rest_framework.test.APIClient object at 0x0000010FFF8ABFA0>
moderator = <YamdbUser: TestModerator>

    def test_06_comment_detail_not_auth(self, admin_client, admin, client,
                                        user_client, user, moderator_client,
                                        moderator):
        author_map = {
            admin: admin_client,
            user: user_client,
            moderator: moderator_client
        }
>       comments, reviews, titles = create_comments(admin_client, author_map)

tests\test_06_comment.py:308: 
_ _ _ _ _ _ _ _ _ _ _ _ _ _ _ _ _ _ _ _ _ _ _ _ _ _ _ _ _ _ _ _ _ _ _ _ _ _ _ _
tests\utils.py:271: in create_comments
    response = create_single_comment(
_ _ _ _ _ _ _ _ _ _ _ _ _ _ _ _ _ _ _ _ _ _ _ _ _ _ _ _ _ _ _ _ _ _ _ _ _ _ _ _

client = <rest_framework.test.APIClient object at 0x0000010FFF9D7B80>
title_id = 33, review_id = 33, text = 'comment number 1'

    def create_single_comment(client, title_id, review_id, text):
        data = {'text': text}
        response = client.post(
            f'/api/v1/titles/{title_id}/reviews/{review_id}/comments/',
            data=data
        )
>       assert response.status_code == HTTPStatus.CREATED, (
            '≈сли POST-запрос авторизованного пользовател€ к '
            '`/api/v1/titles/{title_id}/reviews/{review_id}/comments/` содержит '
            'корректные данные - должен вернутьс€ ответ со статусом 201.'
        )
E       AssertionError: ≈сли POST-запрос авторизованного пользовател€ к `/api/v1/titles/{title_id}/reviews/{review_id}/comments/` содержит корректные данные - должен вернутьс€ ответ со статусом 201.

tests\utils.py:172: AssertionError
------------------------------ Captured log call ------------------------------
WARNING  django.request:log.py:224 Not Found: /api/v1/titles/33/reviews/33/comments/
___________ Test06CommentAPI.test_07_comment_detail_put_not_allowed ___________

self = <tests.test_06_comment.Test06CommentAPI object at 0x0000010FD7356280>
admin_client = <rest_framework.test.APIClient object at 0x0000010FFF8E5940>
admin = <YamdbUser: TestAdmin>
user_client = <rest_framework.test.APIClient object at 0x0000010FFF7E7460>
user = <YamdbUser: TestUser>
moderator_client = <rest_framework.test.APIClient object at 0x0000010FFF7E7370>
moderator = <YamdbUser: TestModerator>

    def test_07_comment_detail_put_not_allowed(
            self, admin_client, admin, user_client, user, moderator_client,
            moderator):
        author_map = {
            admin: admin_client,
            user: user_client,
            moderator: moderator_client
        }
>       comments, reviews, titles = create_comments(admin_client, author_map)

tests\test_06_comment.py:354: 
_ _ _ _ _ _ _ _ _ _ _ _ _ _ _ _ _ _ _ _ _ _ _ _ _ _ _ _ _ _ _ _ _ _ _ _ _ _ _ _
tests\utils.py:271: in create_comments
    response = create_single_comment(
_ _ _ _ _ _ _ _ _ _ _ _ _ _ _ _ _ _ _ _ _ _ _ _ _ _ _ _ _ _ _ _ _ _ _ _ _ _ _ _

client = <rest_framework.test.APIClient object at 0x0000010FFF8E5940>
title_id = 35, review_id = 36, text = 'comment number 1'

    def create_single_comment(client, title_id, review_id, text):
        data = {'text': text}
        response = client.post(
            f'/api/v1/titles/{title_id}/reviews/{review_id}/comments/',
            data=data
        )
>       assert response.status_code == HTTPStatus.CREATED, (
            '≈сли POST-запрос авторизованного пользовател€ к '
            '`/api/v1/titles/{title_id}/reviews/{review_id}/comments/` содержит '
            'корректные данные - должен вернутьс€ ответ со статусом 201.'
        )
E       AssertionError: ≈сли POST-запрос авторизованного пользовател€ к `/api/v1/titles/{title_id}/reviews/{review_id}/comments/` содержит корректные данные - должен вернутьс€ ответ со статусом 201.

tests\utils.py:172: AssertionError
------------------------------ Captured log call ------------------------------
WARNING  django.request:log.py:224 Not Found: /api/v1/titles/35/reviews/36/comments/
-------------------------- Captured stderr teardown ---------------------------
Destroying test database for alias 'default' ('file:memorydb_default?mode=memory&cache=shared')...
============================== warnings summary ===============================
tests/test_01_users.py::Test01UserAPI::test_04_users_get_admin
tests/test_01_users.py::Test01UserAPI::test_04_02_users_get_search
  f:\Python\_Dev\api_yamdb\.venv\lib\site-packages\rest_framework\pagination.py:200: UnorderedObjectListWarning: Pagination may yield inconsistent results with an unordered object_list: <class 'users.models.YamdbUser'> QuerySet.
    paginator = self.django_paginator_class(queryset, page_size)

tests/test_02_category.py::Test02CategoryAPI::test_01_category_not_auth
tests/test_02_category.py::Test02CategoryAPI::test_02_category_with_admin_user
tests/test_02_category.py::Test02CategoryAPI::test_04_category_delete_admin
  f:\Python\_Dev\api_yamdb\.venv\lib\site-packages\rest_framework\pagination.py:200: UnorderedObjectListWarning: Pagination may yield inconsistent results with an unordered object_list: <class 'reviews.models.Category'> QuerySet.
    paginator = self.django_paginator_class(queryset, page_size)

tests/test_03_genre.py::Test03GenreAPI::test_01_genre_not_auth
tests/test_03_genre.py::Test03GenreAPI::test_02_genre
tests/test_03_genre.py::Test03GenreAPI::test_04_genres_delete
  f:\Python\_Dev\api_yamdb\.venv\lib\site-packages\rest_framework\pagination.py:200: UnorderedObjectListWarning: Pagination may yield inconsistent results with an unordered object_list: <class 'reviews.models.Genre'> QuerySet.
    paginator = self.django_paginator_class(queryset, page_size)

-- Docs: https://docs.pytest.org/en/stable/warnings.html
=========================== short test summary info ===========================
FAILED tests/test_00_user_registration.py::Test00UserRegistration::test_get_new_confirmation_code_for_existing_user
FAILED tests/test_00_user_registration.py::Test00UserRegistration::test_get_confirmation_code_for_user_created_by_admin
FAILED tests/test_01_users.py::Test01UserAPI::test_04_02_users_get_search - A...
FAILED tests/test_01_users.py::Test01UserAPI::test_07_05_users_username_put_not_allowed
FAILED tests/test_01_users.py::Test01UserAPI::test_09_users_me_get - TypeErro...
FAILED tests/test_01_users.py::Test01UserAPI::test_10_01_users_me_patch - Ass...
FAILED tests/test_01_users.py::Test01UserAPI::test_10_02_users_me_has_field_validation[data0-messege0]
FAILED tests/test_01_users.py::Test01UserAPI::test_10_02_users_me_has_field_validation[data1-messege1]
FAILED tests/test_01_users.py::Test01UserAPI::test_10_02_users_me_has_field_validation[data2-messege2]
FAILED tests/test_01_users.py::Test01UserAPI::test_10_02_users_me_has_field_validation[data3-messege3]
FAILED tests/test_01_users.py::Test01UserAPI::test_10_02_users_me_has_field_validation[data4-messege4]
FAILED tests/test_01_users.py::Test01UserAPI::test_10_03_users_me_patch_change_role_not_allowed
FAILED tests/test_02_category.py::Test02CategoryAPI::test_04_category_delete_admin
FAILED tests/test_03_genre.py::Test03GenreAPI::test_04_genres_delete - Assert...
FAILED tests/test_04_title.py::Test04TitleAPI::test_02_title_admin - Assertio...
FAILED tests/test_05_review.py::Test05ReviewAPI::test_02_review_post - Assert...
FAILED tests/test_05_review.py::Test05ReviewAPI::test_03_review_detail_get - ...
FAILED tests/test_06_comment.py::Test06CommentAPI::test_01_comment_not_auth
FAILED tests/test_06_comment.py::Test06CommentAPI::test_02_comment - Assertio...
FAILED tests/test_06_comment.py::Test06CommentAPI::test_03_comment_detail_get
FAILED tests/test_06_comment.py::Test06CommentAPI::test_04_comment_detail__user_patch_delete
FAILED tests/test_06_comment.py::Test06CommentAPI::test_05_comment_detail_admin_and_moderator
FAILED tests/test_06_comment.py::Test06CommentAPI::test_06_comment_detail_not_auth
FAILED tests/test_06_comment.py::Test06CommentAPI::test_07_comment_detail_put_not_allowed
================= 24 failed, 56 passed, 8 warnings in 25.37s ==================
